2023-04-27 15:40:24,906 Traceback (most recent call last):
  File "/home/benches/erpnext_user/env/lib/python3.8/site-packages/rq/worker.py", line 1013, in perform_job
    rv = job.perform()
  File "/home/benches/erpnext_user/env/lib/python3.8/site-packages/rq/job.py", line 709, in perform
    self._result = self._execute()
  File "/home/benches/erpnext_user/env/lib/python3.8/site-packages/rq/job.py", line 732, in _execute
    result = self.func(*self.args, **self.kwargs)
  File "/home/benches/erpnext_user/apps/frappe/frappe/utils/background_jobs.py", line 147, in execute_job
    retval = method(**kwargs)
  File "/home/benches/erpnext_user/apps/frappe/frappe/core/doctype/user/user.py", line 1124, in create_contact
    contact.insert(
  File "/home/benches/erpnext_user/apps/frappe/frappe/model/document.py", line 257, in insert
    self._validate_links()
  File "/home/benches/erpnext_user/apps/frappe/frappe/model/document.py", line 910, in _validate_links
    frappe.throw(_("Could not find {0}").format(msg), frappe.LinkValidationError)
  File "/home/benches/erpnext_user/apps/frappe/frappe/__init__.py", line 504, in throw
    msgprint(
  File "/home/benches/erpnext_user/apps/frappe/frappe/__init__.py", line 479, in msgprint
    _raise_exception()
  File "/home/benches/erpnext_user/apps/frappe/frappe/__init__.py", line 434, in _raise_exception
    raise raise_exception(msg)
frappe.exceptions.LinkValidationError: Could not find User Id: danielsnyasha@outlook.com

2023-04-27 15:40:28,237 Traceback (most recent call last):
  File "/home/benches/erpnext_user/env/lib/python3.8/site-packages/rq/worker.py", line 1013, in perform_job
    rv = job.perform()
  File "/home/benches/erpnext_user/env/lib/python3.8/site-packages/rq/job.py", line 709, in perform
    self._result = self._execute()
  File "/home/benches/erpnext_user/env/lib/python3.8/site-packages/rq/job.py", line 732, in _execute
    result = self.func(*self.args, **self.kwargs)
  File "/home/benches/erpnext_user/apps/frappe/frappe/utils/background_jobs.py", line 147, in execute_job
    retval = method(**kwargs)
  File "/home/benches/erpnext_user/apps/frappe/frappe/core/doctype/user/user.py", line 1124, in create_contact
    contact.insert(
  File "/home/benches/erpnext_user/apps/frappe/frappe/model/document.py", line 257, in insert
    self._validate_links()
  File "/home/benches/erpnext_user/apps/frappe/frappe/model/document.py", line 910, in _validate_links
    frappe.throw(_("Could not find {0}").format(msg), frappe.LinkValidationError)
  File "/home/benches/erpnext_user/apps/frappe/frappe/__init__.py", line 504, in throw
    msgprint(
  File "/home/benches/erpnext_user/apps/frappe/frappe/__init__.py", line 479, in msgprint
    _raise_exception()
  File "/home/benches/erpnext_user/apps/frappe/frappe/__init__.py", line 434, in _raise_exception
    raise raise_exception(msg)
frappe.exceptions.LinkValidationError: Could not find User Id: danielsnyasha@outlook.com

Exception in thread Thread-1:
Traceback (most recent call last):
  File "/usr/lib/python3.8/threading.py", line 932, in _bootstrap_inner
    self.run()
  File "/home/benches/erpnext_user/env/lib/python3.8/site-packages/redis/client.py", line 3718, in run
    pubsub.get_message(ignore_subscribe_messages=True,
  File "/home/benches/erpnext_user/env/lib/python3.8/site-packages/redis/client.py", line 3617, in get_message
    response = self.parse_response(block=False, timeout=timeout)
  File "/home/benches/erpnext_user/env/lib/python3.8/site-packages/redis/client.py", line 3503, in parse_response
    if not block and not conn.can_read(timeout=timeout):
  File "/home/benches/erpnext_user/env/lib/python3.8/site-packages/redis/connection.py", line 734, in can_read
    return self._parser.can_read(timeout)
  File "/home/benches/erpnext_user/env/lib/python3.8/site-packages/redis/connection.py", line 416, in can_read
    return self.read_from_socket(timeout=timeout,
  File "/home/benches/erpnext_user/env/lib/python3.8/site-packages/redis/connection.py", line 429, in read_from_socket
    raise ConnectionError(SERVER_CLOSED_CONNECTION_ERROR)
redis.exceptions.ConnectionError: Connection closed by server.
2023-04-27 15:44:17,086 Worker rq:worker:6aaf6a54eb354fabb67ffc075f9005c0: found an unhandled exception, quitting...
Traceback (most recent call last):
  File "/home/benches/erpnext_user/env/lib/python3.8/site-packages/redis/connection.py", line 1198, in get_connection
    if connection.can_read():
  File "/home/benches/erpnext_user/env/lib/python3.8/site-packages/redis/connection.py", line 734, in can_read
    return self._parser.can_read(timeout)
  File "/home/benches/erpnext_user/env/lib/python3.8/site-packages/redis/connection.py", line 416, in can_read
    return self.read_from_socket(timeout=timeout,
  File "/home/benches/erpnext_user/env/lib/python3.8/site-packages/redis/connection.py", line 429, in read_from_socket
    raise ConnectionError(SERVER_CLOSED_CONNECTION_ERROR)
redis.exceptions.ConnectionError: Connection closed by server.

During handling of the above exception, another exception occurred:

Traceback (most recent call last):
  File "/home/benches/erpnext_user/env/lib/python3.8/site-packages/redis/connection.py", line 559, in connect
    sock = self._connect()
  File "/home/benches/erpnext_user/env/lib/python3.8/site-packages/redis/connection.py", line 615, in _connect
    raise err
  File "/home/benches/erpnext_user/env/lib/python3.8/site-packages/redis/connection.py", line 603, in _connect
    sock.connect(socket_address)
ConnectionRefusedError: [Errno 111] Connection refused

During handling of the above exception, another exception occurred:

Traceback (most recent call last):
  File "/home/benches/erpnext_user/env/lib/python3.8/site-packages/rq/worker.py", line 595, in work
    self.execute_job(job, queue)
  File "/home/benches/erpnext_user/env/lib/python3.8/site-packages/rq/worker.py", line 856, in execute_job
    self.monitor_work_horse(job, queue)
  File "/home/benches/erpnext_user/env/lib/python3.8/site-packages/rq/worker.py", line 786, in monitor_work_horse
    retpid, ret_val = self.wait_for_horse()
  File "/home/benches/erpnext_user/env/lib/python3.8/site-packages/rq/worker.py", line 433, in wait_for_horse
    pid, stat = os.waitpid(self.horse_pid, 0)
  File "/home/benches/erpnext_user/env/lib/python3.8/site-packages/rq/worker.py", line 461, in request_stop
    self._shutdown()
  File "/home/benches/erpnext_user/env/lib/python3.8/site-packages/rq/worker.py", line 470, in _shutdown
    self.set_shutdown_requested_date()
  File "/home/benches/erpnext_user/env/lib/python3.8/site-packages/rq/worker.py", line 330, in set_shutdown_requested_date
    self.connection.hset(self.key, 'shutdown_requested_date', utcformat(utcnow()))
  File "/home/benches/erpnext_user/env/lib/python3.8/site-packages/redis/client.py", line 3050, in hset
    return self.execute_command('HSET', name, *items)
  File "/home/benches/erpnext_user/env/lib/python3.8/site-packages/redis/client.py", line 898, in execute_command
    conn = self.connection or pool.get_connection(command_name, **options)
  File "/home/benches/erpnext_user/env/lib/python3.8/site-packages/redis/connection.py", line 1202, in get_connection
    connection.connect()
  File "/home/benches/erpnext_user/env/lib/python3.8/site-packages/redis/connection.py", line 563, in connect
    raise ConnectionError(self._error_message(e))
redis.exceptions.ConnectionError: Error 111 connecting to localhost:11000. Connection refused.
Traceback (most recent call last):
  File "/home/benches/erpnext_user/env/lib/python3.8/site-packages/redis/connection.py", line 559, in connect
    sock = self._connect()
  File "/home/benches/erpnext_user/env/lib/python3.8/site-packages/redis/connection.py", line 615, in _connect
    raise err
  File "/home/benches/erpnext_user/env/lib/python3.8/site-packages/redis/connection.py", line 603, in _connect
    sock.connect(socket_address)
ConnectionRefusedError: [Errno 111] Connection refused

During handling of the above exception, another exception occurred:

Traceback (most recent call last):
  File "/usr/lib/python3.8/runpy.py", line 194, in _run_module_as_main
    return _run_code(code, main_globals, None,
  File "/usr/lib/python3.8/runpy.py", line 87, in _run_code
    exec(code, run_globals)
  File "/home/benches/erpnext_user/apps/frappe/frappe/utils/bench_helper.py", line 110, in <module>
    main()
  File "/home/benches/erpnext_user/apps/frappe/frappe/utils/bench_helper.py", line 20, in main
    click.Group(commands=commands)(prog_name="bench")
  File "/home/benches/erpnext_user/env/lib/python3.8/site-packages/click/core.py", line 829, in __call__
    return self.main(*args, **kwargs)
  File "/home/benches/erpnext_user/env/lib/python3.8/site-packages/click/core.py", line 782, in main
    rv = self.invoke(ctx)
  File "/home/benches/erpnext_user/env/lib/python3.8/site-packages/click/core.py", line 1259, in invoke
    return _process_result(sub_ctx.command.invoke(sub_ctx))
  File "/home/benches/erpnext_user/env/lib/python3.8/site-packages/click/core.py", line 1259, in invoke
    return _process_result(sub_ctx.command.invoke(sub_ctx))
  File "/home/benches/erpnext_user/env/lib/python3.8/site-packages/click/core.py", line 1066, in invoke
    return ctx.invoke(self.callback, **ctx.params)
  File "/home/benches/erpnext_user/env/lib/python3.8/site-packages/click/core.py", line 610, in invoke
    return callback(*args, **kwargs)
  File "/home/benches/erpnext_user/apps/frappe/frappe/commands/scheduler.py", line 203, in start_worker
    start_worker(queue, quiet=quiet)
  File "/home/benches/erpnext_user/apps/frappe/frappe/utils/background_jobs.py", line 202, in start_worker
    Worker(queues, name=get_worker_name(queue)).work(
  File "/home/benches/erpnext_user/env/lib/python3.8/site-packages/rq/worker.py", line 626, in work
    self.register_death()
  File "/home/benches/erpnext_user/env/lib/python3.8/site-packages/rq/worker.py", line 326, in register_death
    p.execute()
  File "/home/benches/erpnext_user/env/lib/python3.8/site-packages/redis/client.py", line 4012, in execute
    conn = self.connection_pool.get_connection('MULTI',
  File "/home/benches/erpnext_user/env/lib/python3.8/site-packages/redis/connection.py", line 1192, in get_connection
    connection.connect()
  File "/home/benches/erpnext_user/env/lib/python3.8/site-packages/redis/connection.py", line 563, in connect
    raise ConnectionError(self._error_message(e))
redis.exceptions.ConnectionError: Error 111 connecting to localhost:11000. Connection refused.
2023-04-27 15:44:19,424 Traceback (most recent call last):
  File "/home/benches/erpnext_user/env/lib/python3.8/site-packages/redis/connection.py", line 1198, in get_connection
    if connection.can_read():
  File "/home/benches/erpnext_user/env/lib/python3.8/site-packages/redis/connection.py", line 734, in can_read
    return self._parser.can_read(timeout)
  File "/home/benches/erpnext_user/env/lib/python3.8/site-packages/redis/connection.py", line 416, in can_read
    return self.read_from_socket(timeout=timeout,
  File "/home/benches/erpnext_user/env/lib/python3.8/site-packages/redis/connection.py", line 429, in read_from_socket
    raise ConnectionError(SERVER_CLOSED_CONNECTION_ERROR)
redis.exceptions.ConnectionError: Connection closed by server.

During handling of the above exception, another exception occurred:

Traceback (most recent call last):
  File "/home/benches/erpnext_user/env/lib/python3.8/site-packages/redis/connection.py", line 559, in connect
    sock = self._connect()
  File "/home/benches/erpnext_user/env/lib/python3.8/site-packages/redis/connection.py", line 615, in _connect
    raise err
  File "/home/benches/erpnext_user/env/lib/python3.8/site-packages/redis/connection.py", line 603, in _connect
    sock.connect(socket_address)
ConnectionRefusedError: [Errno 111] Connection refused

During handling of the above exception, another exception occurred:

Traceback (most recent call last):
  File "/home/benches/erpnext_user/env/lib/python3.8/site-packages/rq/worker.py", line 1020, in perform_job
    self.handle_job_success(job=job,
  File "/home/benches/erpnext_user/env/lib/python3.8/site-packages/rq/worker.py", line 970, in handle_job_success
    pipeline.watch(job.dependents_key)
  File "/home/benches/erpnext_user/env/lib/python3.8/site-packages/redis/client.py", line 4041, in watch
    return self.execute_command('WATCH', *names)
  File "/home/benches/erpnext_user/env/lib/python3.8/site-packages/redis/client.py", line 3822, in execute_command
    return self.immediate_execute_command(*args, **kwargs)
  File "/home/benches/erpnext_user/env/lib/python3.8/site-packages/redis/client.py", line 3836, in immediate_execute_command
    conn = self.connection_pool.get_connection(command_name,
  File "/home/benches/erpnext_user/env/lib/python3.8/site-packages/redis/connection.py", line 1202, in get_connection
    connection.connect()
  File "/home/benches/erpnext_user/env/lib/python3.8/site-packages/redis/connection.py", line 563, in connect
    raise ConnectionError(self._error_message(e))
redis.exceptions.ConnectionError: Error 111 connecting to localhost:11000. Connection refused.

/home/benches/erpnext_user/env/lib/python3.8/site-packages/botocore/httpsession.py:18: DeprecationWarning: 'urllib3.contrib.pyopenssl' module is deprecated and will be removed in a future release of urllib3 2.x. Read more in this issue: https://github.com/urllib3/urllib3/issues/2680
  from urllib3.contrib.pyopenssl import orig_util_SSLContext as SSLContext
Exception in thread Thread-1:
Traceback (most recent call last):
  File "/usr/lib/python3.8/threading.py", line 932, in _bootstrap_inner
    self.run()
  File "/home/benches/erpnext_user/env/lib/python3.8/site-packages/redis/client.py", line 3718, in run
    pubsub.get_message(ignore_subscribe_messages=True,
  File "/home/benches/erpnext_user/env/lib/python3.8/site-packages/redis/client.py", line 3617, in get_message
    response = self.parse_response(block=False, timeout=timeout)
  File "/home/benches/erpnext_user/env/lib/python3.8/site-packages/redis/client.py", line 3503, in parse_response
    if not block and not conn.can_read(timeout=timeout):
  File "/home/benches/erpnext_user/env/lib/python3.8/site-packages/redis/connection.py", line 734, in can_read
    return self._parser.can_read(timeout)
  File "/home/benches/erpnext_user/env/lib/python3.8/site-packages/redis/connection.py", line 416, in can_read
    return self.read_from_socket(timeout=timeout,
  File "/home/benches/erpnext_user/env/lib/python3.8/site-packages/redis/connection.py", line 429, in read_from_socket
    raise ConnectionError(SERVER_CLOSED_CONNECTION_ERROR)
redis.exceptions.ConnectionError: Connection closed by server.
2023-04-27 15:51:50,428 Worker rq:worker:a070554655cb41b695fe1b21107d3ca6: found an unhandled exception, quitting...
Traceback (most recent call last):
  File "/home/benches/erpnext_user/env/lib/python3.8/site-packages/redis/connection.py", line 1198, in get_connection
    if connection.can_read():
  File "/home/benches/erpnext_user/env/lib/python3.8/site-packages/redis/connection.py", line 734, in can_read
    return self._parser.can_read(timeout)
  File "/home/benches/erpnext_user/env/lib/python3.8/site-packages/redis/connection.py", line 416, in can_read
    return self.read_from_socket(timeout=timeout,
  File "/home/benches/erpnext_user/env/lib/python3.8/site-packages/redis/connection.py", line 429, in read_from_socket
    raise ConnectionError(SERVER_CLOSED_CONNECTION_ERROR)
redis.exceptions.ConnectionError: Connection closed by server.

During handling of the above exception, another exception occurred:

Traceback (most recent call last):
  File "/home/benches/erpnext_user/env/lib/python3.8/site-packages/redis/connection.py", line 559, in connect
    sock = self._connect()
  File "/home/benches/erpnext_user/env/lib/python3.8/site-packages/redis/connection.py", line 615, in _connect
    raise err
  File "/home/benches/erpnext_user/env/lib/python3.8/site-packages/redis/connection.py", line 603, in _connect
    sock.connect(socket_address)
ConnectionRefusedError: [Errno 111] Connection refused

During handling of the above exception, another exception occurred:

Traceback (most recent call last):
  File "/home/benches/erpnext_user/env/lib/python3.8/site-packages/rq/worker.py", line 595, in work
    self.execute_job(job, queue)
  File "/home/benches/erpnext_user/env/lib/python3.8/site-packages/rq/worker.py", line 856, in execute_job
    self.monitor_work_horse(job, queue)
  File "/home/benches/erpnext_user/env/lib/python3.8/site-packages/rq/worker.py", line 786, in monitor_work_horse
    retpid, ret_val = self.wait_for_horse()
  File "/home/benches/erpnext_user/env/lib/python3.8/site-packages/rq/worker.py", line 433, in wait_for_horse
    pid, stat = os.waitpid(self.horse_pid, 0)
  File "/home/benches/erpnext_user/env/lib/python3.8/site-packages/rq/worker.py", line 461, in request_stop
    self._shutdown()
  File "/home/benches/erpnext_user/env/lib/python3.8/site-packages/rq/worker.py", line 470, in _shutdown
    self.set_shutdown_requested_date()
  File "/home/benches/erpnext_user/env/lib/python3.8/site-packages/rq/worker.py", line 330, in set_shutdown_requested_date
    self.connection.hset(self.key, 'shutdown_requested_date', utcformat(utcnow()))
  File "/home/benches/erpnext_user/env/lib/python3.8/site-packages/redis/client.py", line 3050, in hset
    return self.execute_command('HSET', name, *items)
  File "/home/benches/erpnext_user/env/lib/python3.8/site-packages/redis/client.py", line 898, in execute_command
    conn = self.connection or pool.get_connection(command_name, **options)
  File "/home/benches/erpnext_user/env/lib/python3.8/site-packages/redis/connection.py", line 1202, in get_connection
    connection.connect()
  File "/home/benches/erpnext_user/env/lib/python3.8/site-packages/redis/connection.py", line 563, in connect
    raise ConnectionError(self._error_message(e))
redis.exceptions.ConnectionError: Error 111 connecting to localhost:11000. Connection refused.
Traceback (most recent call last):
  File "/home/benches/erpnext_user/env/lib/python3.8/site-packages/redis/connection.py", line 559, in connect
    sock = self._connect()
  File "/home/benches/erpnext_user/env/lib/python3.8/site-packages/redis/connection.py", line 615, in _connect
    raise err
  File "/home/benches/erpnext_user/env/lib/python3.8/site-packages/redis/connection.py", line 603, in _connect
    sock.connect(socket_address)
ConnectionRefusedError: [Errno 111] Connection refused

During handling of the above exception, another exception occurred:

Traceback (most recent call last):
  File "/usr/lib/python3.8/runpy.py", line 194, in _run_module_as_main
    return _run_code(code, main_globals, None,
  File "/usr/lib/python3.8/runpy.py", line 87, in _run_code
    exec(code, run_globals)
  File "/home/benches/erpnext_user/apps/frappe/frappe/utils/bench_helper.py", line 110, in <module>
    main()
  File "/home/benches/erpnext_user/apps/frappe/frappe/utils/bench_helper.py", line 20, in main
    click.Group(commands=commands)(prog_name="bench")
  File "/home/benches/erpnext_user/env/lib/python3.8/site-packages/click/core.py", line 829, in __call__
    return self.main(*args, **kwargs)
  File "/home/benches/erpnext_user/env/lib/python3.8/site-packages/click/core.py", line 782, in main
    rv = self.invoke(ctx)
  File "/home/benches/erpnext_user/env/lib/python3.8/site-packages/click/core.py", line 1259, in invoke
    return _process_result(sub_ctx.command.invoke(sub_ctx))
  File "/home/benches/erpnext_user/env/lib/python3.8/site-packages/click/core.py", line 1259, in invoke
    return _process_result(sub_ctx.command.invoke(sub_ctx))
  File "/home/benches/erpnext_user/env/lib/python3.8/site-packages/click/core.py", line 1066, in invoke
    return ctx.invoke(self.callback, **ctx.params)
  File "/home/benches/erpnext_user/env/lib/python3.8/site-packages/click/core.py", line 610, in invoke
    return callback(*args, **kwargs)
  File "/home/benches/erpnext_user/apps/frappe/frappe/commands/scheduler.py", line 203, in start_worker
    start_worker(queue, quiet=quiet)
  File "/home/benches/erpnext_user/apps/frappe/frappe/utils/background_jobs.py", line 202, in start_worker
    Worker(queues, name=get_worker_name(queue)).work(
  File "/home/benches/erpnext_user/env/lib/python3.8/site-packages/rq/worker.py", line 626, in work
    self.register_death()
  File "/home/benches/erpnext_user/env/lib/python3.8/site-packages/rq/worker.py", line 326, in register_death
    p.execute()
  File "/home/benches/erpnext_user/env/lib/python3.8/site-packages/redis/client.py", line 4012, in execute
    conn = self.connection_pool.get_connection('MULTI',
  File "/home/benches/erpnext_user/env/lib/python3.8/site-packages/redis/connection.py", line 1192, in get_connection
    connection.connect()
  File "/home/benches/erpnext_user/env/lib/python3.8/site-packages/redis/connection.py", line 563, in connect
    raise ConnectionError(self._error_message(e))
redis.exceptions.ConnectionError: Error 111 connecting to localhost:11000. Connection refused.
2023-04-27 15:51:51,714 Traceback (most recent call last):
  File "/home/benches/erpnext_user/env/lib/python3.8/site-packages/redis/connection.py", line 1198, in get_connection
    if connection.can_read():
  File "/home/benches/erpnext_user/env/lib/python3.8/site-packages/redis/connection.py", line 734, in can_read
    return self._parser.can_read(timeout)
  File "/home/benches/erpnext_user/env/lib/python3.8/site-packages/redis/connection.py", line 416, in can_read
    return self.read_from_socket(timeout=timeout,
  File "/home/benches/erpnext_user/env/lib/python3.8/site-packages/redis/connection.py", line 429, in read_from_socket
    raise ConnectionError(SERVER_CLOSED_CONNECTION_ERROR)
redis.exceptions.ConnectionError: Connection closed by server.

During handling of the above exception, another exception occurred:

Traceback (most recent call last):
  File "/home/benches/erpnext_user/env/lib/python3.8/site-packages/redis/connection.py", line 559, in connect
    sock = self._connect()
  File "/home/benches/erpnext_user/env/lib/python3.8/site-packages/redis/connection.py", line 615, in _connect
    raise err
  File "/home/benches/erpnext_user/env/lib/python3.8/site-packages/redis/connection.py", line 603, in _connect
    sock.connect(socket_address)
ConnectionRefusedError: [Errno 111] Connection refused

During handling of the above exception, another exception occurred:

Traceback (most recent call last):
  File "/home/benches/erpnext_user/env/lib/python3.8/site-packages/rq/worker.py", line 1020, in perform_job
    self.handle_job_success(job=job,
  File "/home/benches/erpnext_user/env/lib/python3.8/site-packages/rq/worker.py", line 970, in handle_job_success
    pipeline.watch(job.dependents_key)
  File "/home/benches/erpnext_user/env/lib/python3.8/site-packages/redis/client.py", line 4041, in watch
    return self.execute_command('WATCH', *names)
  File "/home/benches/erpnext_user/env/lib/python3.8/site-packages/redis/client.py", line 3822, in execute_command
    return self.immediate_execute_command(*args, **kwargs)
  File "/home/benches/erpnext_user/env/lib/python3.8/site-packages/redis/client.py", line 3836, in immediate_execute_command
    conn = self.connection_pool.get_connection(command_name,
  File "/home/benches/erpnext_user/env/lib/python3.8/site-packages/redis/connection.py", line 1202, in get_connection
    connection.connect()
  File "/home/benches/erpnext_user/env/lib/python3.8/site-packages/redis/connection.py", line 563, in connect
    raise ConnectionError(self._error_message(e))
redis.exceptions.ConnectionError: Error 111 connecting to localhost:11000. Connection refused.

/home/benches/erpnext_user/env/lib/python3.8/site-packages/botocore/httpsession.py:18: DeprecationWarning: 'urllib3.contrib.pyopenssl' module is deprecated and will be removed in a future release of urllib3 2.x. Read more in this issue: https://github.com/urllib3/urllib3/issues/2680
  from urllib3.contrib.pyopenssl import orig_util_SSLContext as SSLContext
/home/benches/erpnext_user/env/lib/python3.8/site-packages/botocore/httpsession.py:18: DeprecationWarning: 'urllib3.contrib.pyopenssl' module is deprecated and will be removed in a future release of urllib3 2.x. Read more in this issue: https://github.com/urllib3/urllib3/issues/2680
  from urllib3.contrib.pyopenssl import orig_util_SSLContext as SSLContext
fatal: No remote configured to list refs from.
Exception in thread Thread-12023-04-27 16:35:13,317 Could not connect to Redis instance: Connection closed by server. Retrying in 1 seconds...
:
Traceback (most recent call last):
  File "/usr/lib/python3.8/threading.py", line 932, in _bootstrap_inner
    self.run()
  File "/home/benches/erpnext_user/env/lib/python3.8/site-packages/redis/client.py", line 3718, in run
    pubsub.get_message(ignore_subscribe_messages=True,
  File "/home/benches/erpnext_user/env/lib/python3.8/site-packages/redis/client.py", line 3617, in get_message
    response = self.parse_response(block=False, timeout=timeout)
Traceback (most recent call last):
  File "/home/benches/erpnext_user/env/lib/python3.8/site-packages/redis/connection.py", line 559, in connect
    sock = self._connect()
  File "/home/benches/erpnext_user/env/lib/python3.8/site-packages/redis/connection.py", line 615, in _connect
    raise err
  File "/home/benches/erpnext_user/env/lib/python3.8/site-packages/redis/connection.py", line 603, in _connect
    sock.connect(socket_address)
ConnectionRefusedError: [Errno 111] Connection refused

During handling of the above exception, another exception occurred:

Traceback (most recent call last):
  File "/usr/lib/python3.8/runpy.py", line 194, in _run_module_as_main
    return _run_code(code, main_globals, None,
  File "/usr/lib/python3.8/runpy.py", line 87, in _run_code
    exec(code, run_globals)
  File "/home/benches/erpnext_user/apps/frappe/frappe/utils/bench_helper.py", line 110, in <module>
    main()
  File "/home/benches/erpnext_user/apps/frappe/frappe/utils/bench_helper.py", line 20, in main
    click.Group(commands=commands)(prog_name="bench")
  File "/home/benches/erpnext_user/env/lib/python3.8/site-packages/click/core.py", line 829, in __call__
    return self.main(*args, **kwargs)
  File "/home/benches/erpnext_user/env/lib/python3.8/site-packages/click/core.py", line 782, in main
  File "/home/benches/erpnext_user/env/lib/python3.8/site-packages/redis/client.py", line 3503, in parse_response
    if not block and not conn.can_read(timeout=timeout):
  File "/home/benches/erpnext_user/env/lib/python3.8/site-packages/redis/connection.py", line 734, in can_read
    return self._parser.can_read(timeout)    rv = self.invoke(ctx)
  File "/home/benches/erpnext_user/env/lib/python3.8/site-packages/click/core.py", line 1259, in invoke
    
  File "/home/benches/erpnext_user/env/lib/python3.8/site-packages/redis/connection.py", line 416, in can_read
    return self.read_from_socket(timeout=timeout,
  File "/home/benches/erpnext_user/env/lib/python3.8/site-packages/redis/connection.py", line 429, in read_from_socket
return _process_result(sub_ctx.command.invoke(sub_ctx))
  File "/home/benches/erpnext_user/env/lib/python3.8/site-packages/click/core.py", line 1259, in invoke
    return _process_result(sub_ctx.command.invoke(sub_ctx))
  File "/home/benches/erpnext_user/env/lib/python3.8/site-packages/click/core.py", line 1066, in invoke
        return ctx.invoke(self.callback, **ctx.params)
  File "/home/benches/erpnext_user/env/lib/python3.8/site-packages/click/core.py", line 610, in invoke
raise ConnectionError(SERVER_CLOSED_CONNECTION_ERROR)
redis.exceptions.ConnectionError: Connection closed by server.
    return callback(*args, **kwargs)
  File "/home/benches/erpnext_user/apps/frappe/frappe/commands/scheduler.py", line 203, in start_worker
    start_worker(queue, quiet=quiet)
  File "/home/benches/erpnext_user/apps/frappe/frappe/utils/background_jobs.py", line 202, in start_worker
    Worker(queues, name=get_worker_name(queue)).work(
  File "/home/benches/erpnext_user/env/lib/python3.8/site-packages/rq/worker.py", line 626, in work
    self.register_death()
  File "/home/benches/erpnext_user/env/lib/python3.8/site-packages/rq/worker.py", line 326, in register_death
    p.execute()
  File "/home/benches/erpnext_user/env/lib/python3.8/site-packages/redis/client.py", line 4012, in execute
    conn = self.connection_pool.get_connection('MULTI',
  File "/home/benches/erpnext_user/env/lib/python3.8/site-packages/redis/connection.py", line 1192, in get_connection
    connection.connect()
  File "/home/benches/erpnext_user/env/lib/python3.8/site-packages/redis/connection.py", line 563, in connect
    raise ConnectionError(self._error_message(e))
redis.exceptions.ConnectionError: Error 111 connecting to localhost:11000. Connection refused.
Exception in thread Thread-1:
Traceback (most recent call last):
  File "/usr/lib/python3.8/threading.py", line 932, in _bootstrap_inner
    self.run()
  File "/home/benches/erpnext_user/env/lib/python3.8/site-packages/redis/client.py", line 3718, in run
    pubsub.get_message(ignore_subscribe_messages=True,
  File "/home/benches/erpnext_user/env/lib/python3.8/site-packages/redis/client.py", line 3617, in get_message
    response = self.parse_response(block=False, timeout=timeout)
  File "/home/benches/erpnext_user/env/lib/python3.8/site-packages/redis/client.py", line 3503, in parse_response
    if not block and not conn.can_read(timeout=timeout):
  File "/home/benches/erpnext_user/env/lib/python3.8/site-packages/redis/connection.py", line 734, in can_read
    return self._parser.can_read(timeout)
  File "/home/benches/erpnext_user/env/lib/python3.8/site-packages/redis/connection.py", line 416, in can_read
    return self.read_from_socket(timeout=timeout,
  File "/home/benches/erpnext_user/env/lib/python3.8/site-packages/redis/connection.py", line 429, in read_from_socket
    raise ConnectionError(SERVER_CLOSED_CONNECTION_ERROR)
redis.exceptions.ConnectionError: Connection closed by server.
Exception in thread Thread-1:
Traceback (most recent call last):
  File "/usr/lib/python3.8/threading.py", line 932, in _bootstrap_inner
    self.run()
  File "/home/benches/erpnext_user/env/lib/python3.8/site-packages/redis/client.py", line 3718, in run
    pubsub.get_message(ignore_subscribe_messages=True,
  File "/home/benches/erpnext_user/env/lib/python3.8/site-packages/redis/client.py", line 3617, in get_message
    response = self.parse_response(block=False, timeout=timeout)
  File "/home/benches/erpnext_user/env/lib/python3.8/site-packages/redis/client.py", line 3503, in parse_response
    if not block and not conn.can_read(timeout=timeout):
  File "/home/benches/erpnext_user/env/lib/python3.8/site-packages/redis/connection.py", line 734, in can_read
    return self._parser.can_read(timeout)
  File "/home/benches/erpnext_user/env/lib/python3.8/site-packages/redis/connection.py", line 416, in can_read
    return self.read_from_socket(timeout=timeout,
  File "/home/benches/erpnext_user/env/lib/python3.8/site-packages/redis/connection.py", line 429, in read_from_socket
    raise ConnectionError(SERVER_CLOSED_CONNECTION_ERROR)
redis.exceptions.ConnectionError: Connection closed by server.
/home/benches/erpnext_user/env/lib/python3.8/site-packages/botocore/httpsession.py:18: DeprecationWarning: 'urllib3.contrib.pyopenssl' module is deprecated and will be removed in a future release of urllib3 2.x. Read more in this issue: https://github.com/urllib3/urllib3/issues/2680
  from urllib3.contrib.pyopenssl import orig_util_SSLContext as SSLContext
fatal: No remote configured to list refs from.
/home/benches/erpnext_user/env/lib/python3.8/site-packages/botocore/httpsession.py:18: DeprecationWarning: 'urllib3.contrib.pyopenssl' module is deprecated and will be removed in a future release of urllib3 2.x. Read more in this issue: https://github.com/urllib3/urllib3/issues/2680
  from urllib3.contrib.pyopenssl import orig_util_SSLContext as SSLContext
Exception in thread Thread-1:
Traceback (most recent call last):
  File "/usr/lib/python3.8/threading.py", line 932, in _bootstrap_inner
    self.run()
  File "/home/benches/erpnext_user/env/lib/python3.8/site-packages/redis/client.py", line 3718, in run
    pubsub.get_message(ignore_subscribe_messages=True,
  File "/home/benches/erpnext_user/env/lib/python3.8/site-packages/redis/client.py", line 3617, in get_message
    response = self.parse_response(block=False, timeout=timeout)
  File "/home/benches/erpnext_user/env/lib/python3.8/site-packages/redis/client.py", line 3503, in parse_response
    if not block and not conn.can_read(timeout=timeout):
  File "/home/benches/erpnext_user/env/lib/python3.8/site-packages/redis/connection.py", line 734, in can_read
    return self._parser.can_read(timeout)
  File "/home/benches/erpnext_user/env/lib/python3.8/site-packages/redis/connection.py", line 416, in can_read
    return self.read_from_socket(timeout=timeout,
  File "/home/benches/erpnext_user/env/lib/python3.8/site-packages/redis/connection.py", line 429, in read_from_socket
    raise ConnectionError(SERVER_CLOSED_CONNECTION_ERROR)
redis.exceptions.ConnectionError: Connection closed by server.
2023-04-29 12:49:08,093 Traceback (most recent call last):
  File "/home/benches/erpnext_user/env/lib/python3.8/site-packages/redis/connection.py", line 1198, in get_connection
    if connection.can_read():
  File "/home/benches/erpnext_user/env/lib/python3.8/site-packages/redis/connection.py", line 734, in can_read
    return self._parser.can_read(timeout)
  File "/home/benches/erpnext_user/env/lib/python3.8/site-packages/redis/connection.py", line 416, in can_read
    return self.read_from_socket(timeout=timeout,
  File "/home/benches/erpnext_user/env/lib/python3.8/site-packages/redis/connection.py", line 429, in read_from_socket
    raise ConnectionError(SERVER_CLOSED_CONNECTION_ERROR)
redis.exceptions.ConnectionError: Connection closed by server.

During handling of the above exception, another exception occurred:

Traceback (most recent call last):
  File "/home/benches/erpnext_user/env/lib/python3.8/site-packages/redis/connection.py", line 559, in connect
    sock = self._connect()
  File "/home/benches/erpnext_user/env/lib/python3.8/site-packages/redis/connection.py", line 615, in _connect
    raise err
  File "/home/benches/erpnext_user/env/lib/python3.8/site-packages/redis/connection.py", line 603, in _connect
    sock.connect(socket_address)
ConnectionRefusedError: [Errno 111] Connection refused

During handling of the above exception, another exception occurred:

Traceback (most recent call last):
  File "/home/benches/erpnext_user/env/lib/python3.8/site-packages/rq/worker.py", line 1020, in perform_job
    self.handle_job_success(job=job,
  File "/home/benches/erpnext_user/env/lib/python3.8/site-packages/rq/worker.py", line 970, in handle_job_success
    pipeline.watch(job.dependents_key)
  File "/home/benches/erpnext_user/env/lib/python3.8/site-packages/redis/client.py", line 4041, in watch
    return self.execute_command('WATCH', *names)
  File "/home/benches/erpnext_user/env/lib/python3.8/site-packages/redis/client.py", line 3822, in execute_command
    return self.immediate_execute_command(*args, **kwargs)
  File "/home/benches/erpnext_user/env/lib/python3.8/site-packages/redis/client.py", line 3836, in immediate_execute_command
    conn = self.connection_pool.get_connection(command_name,
  File "/home/benches/erpnext_user/env/lib/python3.8/site-packages/redis/connection.py", line 1202, in get_connection
    connection.connect()
  File "/home/benches/erpnext_user/env/lib/python3.8/site-packages/redis/connection.py", line 563, in connect
    raise ConnectionError(self._error_message(e))
redis.exceptions.ConnectionError: Error 111 connecting to localhost:11000. Connection refused.

2023-04-29 12:49:08,107 Worker rq:worker:29cb070d2f034e5db558bfc764f46045: found an unhandled exception, quitting...
Traceback (most recent call last):
  File "/home/benches/erpnext_user/env/lib/python3.8/site-packages/redis/connection.py", line 1198, in get_connection
    if connection.can_read():
  File "/home/benches/erpnext_user/env/lib/python3.8/site-packages/redis/connection.py", line 734, in can_read
    return self._parser.can_read(timeout)
  File "/home/benches/erpnext_user/env/lib/python3.8/site-packages/redis/connection.py", line 416, in can_read
    return self.read_from_socket(timeout=timeout,
  File "/home/benches/erpnext_user/env/lib/python3.8/site-packages/redis/connection.py", line 429, in read_from_socket
    raise ConnectionError(SERVER_CLOSED_CONNECTION_ERROR)
redis.exceptions.ConnectionError: Connection closed by server.

During handling of the above exception, another exception occurred:

Traceback (most recent call last):
  File "/home/benches/erpnext_user/env/lib/python3.8/site-packages/redis/connection.py", line 559, in connect
    sock = self._connect()
  File "/home/benches/erpnext_user/env/lib/python3.8/site-packages/redis/connection.py", line 615, in _connect
    raise err
  File "/home/benches/erpnext_user/env/lib/python3.8/site-packages/redis/connection.py", line 603, in _connect
    sock.connect(socket_address)
ConnectionRefusedError: [Errno 111] Connection refused

During handling of the above exception, another exception occurred:

Traceback (most recent call last):
  File "/home/benches/erpnext_user/env/lib/python3.8/site-packages/rq/worker.py", line 595, in work
    self.execute_job(job, queue)
  File "/home/benches/erpnext_user/env/lib/python3.8/site-packages/rq/worker.py", line 856, in execute_job
    self.monitor_work_horse(job, queue)
  File "/home/benches/erpnext_user/env/lib/python3.8/site-packages/rq/worker.py", line 818, in monitor_work_horse
    self.set_current_job_working_time(0)
  File "/home/benches/erpnext_user/env/lib/python3.8/site-packages/rq/worker.py", line 382, in set_current_job_working_time
    connection.hset(self.key, 'current_job_working_time', current_job_working_time)
  File "/home/benches/erpnext_user/env/lib/python3.8/site-packages/redis/client.py", line 3050, in hset
    return self.execute_command('HSET', name, *items)
  File "/home/benches/erpnext_user/env/lib/python3.8/site-packages/redis/client.py", line 898, in execute_command
    conn = self.connection or pool.get_connection(command_name, **options)
  File "/home/benches/erpnext_user/env/lib/python3.8/site-packages/redis/connection.py", line 1202, in get_connection
    connection.connect()
  File "/home/benches/erpnext_user/env/lib/python3.8/site-packages/redis/connection.py", line 563, in connect
    raise ConnectionError(self._error_message(e))
redis.exceptions.ConnectionError: Error 111 connecting to localhost:11000. Connection refused.
Traceback (most recent call last):
  File "/home/benches/erpnext_user/env/lib/python3.8/site-packages/redis/connection.py", line 559, in connect
    sock = self._connect()
  File "/home/benches/erpnext_user/env/lib/python3.8/site-packages/redis/connection.py", line 615, in _connect
    raise err
  File "/home/benches/erpnext_user/env/lib/python3.8/site-packages/redis/connection.py", line 603, in _connect
    sock.connect(socket_address)
ConnectionRefusedError: [Errno 111] Connection refused

During handling of the above exception, another exception occurred:

Traceback (most recent call last):
  File "/usr/lib/python3.8/runpy.py", line 194, in _run_module_as_main
    return _run_code(code, main_globals, None,
  File "/usr/lib/python3.8/runpy.py", line 87, in _run_code
    exec(code, run_globals)
  File "/home/benches/erpnext_user/apps/frappe/frappe/utils/bench_helper.py", line 110, in <module>
    main()
  File "/home/benches/erpnext_user/apps/frappe/frappe/utils/bench_helper.py", line 20, in main
    click.Group(commands=commands)(prog_name="bench")
  File "/home/benches/erpnext_user/env/lib/python3.8/site-packages/click/core.py", line 829, in __call__
    return self.main(*args, **kwargs)
  File "/home/benches/erpnext_user/env/lib/python3.8/site-packages/click/core.py", line 782, in main
    rv = self.invoke(ctx)
  File "/home/benches/erpnext_user/env/lib/python3.8/site-packages/click/core.py", line 1259, in invoke
    return _process_result(sub_ctx.command.invoke(sub_ctx))
  File "/home/benches/erpnext_user/env/lib/python3.8/site-packages/click/core.py", line 1259, in invoke
    return _process_result(sub_ctx.command.invoke(sub_ctx))
  File "/home/benches/erpnext_user/env/lib/python3.8/site-packages/click/core.py", line 1066, in invoke
    return ctx.invoke(self.callback, **ctx.params)
  File "/home/benches/erpnext_user/env/lib/python3.8/site-packages/click/core.py", line 610, in invoke
    return callback(*args, **kwargs)
  File "/home/benches/erpnext_user/apps/frappe/frappe/commands/scheduler.py", line 203, in start_worker
    start_worker(queue, quiet=quiet)
  File "/home/benches/erpnext_user/apps/frappe/frappe/utils/background_jobs.py", line 202, in start_worker
    Worker(queues, name=get_worker_name(queue)).work(
  File "/home/benches/erpnext_user/env/lib/python3.8/site-packages/rq/worker.py", line 626, in work
    self.register_death()
  File "/home/benches/erpnext_user/env/lib/python3.8/site-packages/rq/worker.py", line 326, in register_death
    p.execute()
  File "/home/benches/erpnext_user/env/lib/python3.8/site-packages/redis/client.py", line 4012, in execute
    conn = self.connection_pool.get_connection('MULTI',
  File "/home/benches/erpnext_user/env/lib/python3.8/site-packages/redis/connection.py", line 1192, in get_connection
    connection.connect()
  File "/home/benches/erpnext_user/env/lib/python3.8/site-packages/redis/connection.py", line 563, in connect
    raise ConnectionError(self._error_message(e))
redis.exceptions.ConnectionError: Error 111 connecting to localhost:11000. Connection refused.
Exception in thread Thread-1:
Traceback (most recent call last):
  File "/usr/lib/python3.8/threading.py", line 932, in _bootstrap_inner
    self.run()
  File "/home/benches/erpnext_user/env/lib/python3.8/site-packages/redis/client.py", line 3718, in run
    pubsub.get_message(ignore_subscribe_messages=True,
  File "/home/benches/erpnext_user/env/lib/python3.8/site-packages/redis/client.py", line 3617, in get_message
    response = self.parse_response(block=False, timeout=timeout)
  File "/home/benches/erpnext_user/env/lib/python3.8/site-packages/redis/client.py", line 3503, in parse_response
    if not block and not conn.can_read(timeout=timeout):
  File "/home/benches/erpnext_user/env/lib/python3.8/site-packages/redis/connection.py", line 734, in can_read
    return self._parser.can_read(timeout)
  File "/home/benches/erpnext_user/env/lib/python3.8/site-packages/redis/connection.py", line 416, in can_read
    return self.read_from_socket(timeout=timeout,
  File "/home/benches/erpnext_user/env/lib/python3.8/site-packages/redis/connection.py", line 429, in read_from_socket
    raise ConnectionError(SERVER_CLOSED_CONNECTION_ERROR)
redis.exceptions.ConnectionError: Connection closed by server.
2023-04-29 18:56:48,446 Could not connect to Redis instance: Connection closed by server. Retrying in 1 seconds...
Traceback (most recent call last):
  File "/home/benches/erpnext_user/env/lib/python3.8/site-packages/redis/connection.py", line 559, in connect
    sock = self._connect()
  File "/home/benches/erpnext_user/env/lib/python3.8/site-packages/redis/connection.py", line 615, in _connect
    raise err
  File "/home/benches/erpnext_user/env/lib/python3.8/site-packages/redis/connection.py", line 603, in _connect
Exception in thread     sock.connect(socket_address)
ConnectionRefusedError: [Errno 111] Connection refused

During handling of the above exception, another exception occurred:

Traceback (most recent call last):
  File "/usr/lib/python3.8/runpy.py", line 194, in _run_module_as_main
Thread-1:
Traceback (most recent call last):
  File "/usr/lib/python3.8/threading.py", line 932, in _bootstrap_inner
    self.run()
  File "/home/benches/erpnext_user/env/lib/python3.8/site-packages/redis/client.py", line 3718, in run
    return _run_code(code, main_globals, None,
  File "/usr/lib/python3.8/runpy.py", line 87, in _run_code
    exec(code, run_globals)
  File "/home/benches/erpnext_user/apps/frappe/frappe/utils/bench_helper.py", line 110, in <module>
    main()
  File "/home/benches/erpnext_user/apps/frappe/frappe/utils/bench_helper.py", line 20, in main
    click.Group(commands=commands)(prog_name="bench")
  File "/home/benches/erpnext_user/env/lib/python3.8/site-packages/click/core.py", line 829, in __call__
    return self.main(*args, **kwargs)
  File "/home/benches/erpnext_user/env/lib/python3.8/site-packages/click/core.py", line 782, in main
    rv = self.invoke(ctx)
  File "/home/benches/erpnext_user/env/lib/python3.8/site-packages/click/core.py", line 1259, in invoke
    return _process_result(sub_ctx.command.invoke(sub_ctx))
  File "/home/benches/erpnext_user/env/lib/python3.8/site-packages/click/core.py", line 1259, in invoke
    pubsub.get_message(ignore_subscribe_messages=True,
  File "/home/benches/erpnext_user/env/lib/python3.8/site-packages/redis/client.py", line 3617, in get_message
    response = self.parse_response(block=False, timeout=timeout)    return _process_result(sub_ctx.command.invoke(sub_ctx))
  File "/home/benches/erpnext_user/env/lib/python3.8/site-packages/click/core.py", line 1066, in invoke

    return ctx.invoke(self.callback, **ctx.params)
  File "/home/benches/erpnext_user/env/lib/python3.8/site-packages/click/core.py", line 610, in invoke
    return callback(*args, **kwargs)
  File "/home/benches/erpnext_user/apps/frappe/frappe/commands/scheduler.py", line 203, in start_worker
      File "/home/benches/erpnext_user/env/lib/python3.8/site-packages/redis/client.py", line 3503, in parse_response
start_worker(queue, quiet=quiet)    if not block and not conn.can_read(timeout=timeout):
  File "/home/benches/erpnext_user/env/lib/python3.8/site-packages/redis/connection.py", line 734, in can_read
    
  File "/home/benches/erpnext_user/apps/frappe/frappe/utils/background_jobs.py", line 202, in start_worker
return self._parser.can_read(timeout)    Worker(queues, name=get_worker_name(queue)).work(
  File "/home/benches/erpnext_user/env/lib/python3.8/site-packages/redis/connection.py", line 416, in can_read
    return self.read_from_socket(timeout=timeout,
  File "/home/benches/erpnext_user/env/lib/python3.8/site-packages/redis/connection.py", line 429, in read_from_socket
    
  File "/home/benches/erpnext_user/env/lib/python3.8/site-packages/rq/worker.py", line 626, in work
raise ConnectionError(SERVER_CLOSED_CONNECTION_ERROR)
redis.exceptions.ConnectionError: Connection closed by server.    self.register_death()

  File "/home/benches/erpnext_user/env/lib/python3.8/site-packages/rq/worker.py", line 326, in register_death
    p.execute()
  File "/home/benches/erpnext_user/env/lib/python3.8/site-packages/redis/client.py", line 4012, in execute
    conn = self.connection_pool.get_connection('MULTI',
  File "/home/benches/erpnext_user/env/lib/python3.8/site-packages/redis/connection.py", line 1192, in get_connection
    connection.connect()
  File "/home/benches/erpnext_user/env/lib/python3.8/site-packages/redis/connection.py", line 563, in connect
    raise ConnectionError(self._error_message(e))
redis.exceptions.ConnectionError: Error 111 connecting to localhost:11000. Connection refused.
/home/benches/erpnext_user/env/lib/python3.8/site-packages/botocore/httpsession.py:18: DeprecationWarning: 'urllib3.contrib.pyopenssl' module is deprecated and will be removed in a future release of urllib3 2.x. Read more in this issue: https://github.com/urllib3/urllib3/issues/2680
  from urllib3.contrib.pyopenssl import orig_util_SSLContext as SSLContext
/home/benches/erpnext_user/env/lib/python3.8/site-packages/botocore/httpsession.py:18: DeprecationWarning: 'urllib3.contrib.pyopenssl' module is deprecated and will be removed in a future release of urllib3 2.x. Read more in this issue: https://github.com/urllib3/urllib3/issues/2680
  from urllib3.contrib.pyopenssl import orig_util_SSLContext as SSLContext
fatal: No remote configured to list refs from.
Exception in thread 2023-04-30 11:42:38,416 Could not connect to Redis instance: Connection closed by server. Retrying in 1 seconds...
Thread-1:
Traceback (most recent call last):
  File "/usr/lib/python3.8/threading.py", line 932, in _bootstrap_inner
    self.run()
  File "/home/benches/erpnext_user/env/lib/python3.8/site-packages/redis/client.py", line 3718, in run
    pubsub.get_message(ignore_subscribe_messages=True,
  File "/home/benches/erpnext_user/env/lib/python3.8/site-packages/redis/client.py", line 3617, in get_message
    response = self.parse_response(block=False, timeout=timeout)
  File "/home/benches/erpnext_user/env/lib/python3.8/site-packages/redis/client.py", line 3503, in parse_response
Exception in thread Thread-1:
Traceback (most recent call last):
  File "/usr/lib/python3.8/threading.py", line 932, in _bootstrap_inner
    self.run()
  File "/home/benches/erpnext_user/env/lib/python3.8/site-packages/redis/client.py", line 3718, in run
    pubsub.get_message(ignore_subscribe_messages=True,
  File "/home/benches/erpnext_user/env/lib/python3.8/site-packages/redis/client.py", line 3617, in get_message
    response = self.parse_response(block=False, timeout=timeout)
  File "/home/benches/erpnext_user/env/lib/python3.8/site-packages/redis/client.py", line 3503, in parse_response
    if not block and not conn.can_read(timeout=timeout):
  File "/home/benches/erpnext_user/env/lib/python3.8/site-packages/redis/connection.py", line 734, in can_read
    return self._parser.can_read(timeout)
  File "/home/benches/erpnext_user/env/lib/python3.8/site-packages/redis/connection.py", line 416, in can_read
    return self.read_from_socket(timeout=timeout,
  File "/home/benches/erpnext_user/env/lib/python3.8/site-packages/redis/connection.py", line 429, in read_from_socket
    raise ConnectionError(SERVER_CLOSED_CONNECTION_ERROR)
redis.exceptions.ConnectionError: Connection closed by server.
2023-04-30 12:01:17,490 Traceback (most recent call last):
  File "/home/benches/erpnext_user/env/lib/python3.8/site-packages/redis/connection.py", line 1198, in get_connection
    if connection.can_read():
  File "/home/benches/erpnext_user/env/lib/python3.8/site-packages/redis/connection.py", line 734, in can_read
    return self._parser.can_read(timeout)
  File "/home/benches/erpnext_user/env/lib/python3.8/site-packages/redis/connection.py", line 416, in can_read
    return self.read_from_socket(timeout=timeout,
  File "/home/benches/erpnext_user/env/lib/python3.8/site-packages/redis/connection.py", line 429, in read_from_socket
    raise ConnectionError(SERVER_CLOSED_CONNECTION_ERROR)
redis.exceptions.ConnectionError: Connection closed by server.

During handling of the above exception, another exception occurred:

Traceback (most recent call last):
  File "/home/benches/erpnext_user/env/lib/python3.8/site-packages/redis/connection.py", line 559, in connect
    sock = self._connect()
  File "/home/benches/erpnext_user/env/lib/python3.8/site-packages/redis/connection.py", line 615, in _connect
    raise err
  File "/home/benches/erpnext_user/env/lib/python3.8/site-packages/redis/connection.py", line 603, in _connect
    sock.connect(socket_address)
ConnectionRefusedError: [Errno 111] Connection refused

During handling of the above exception, another exception occurred:

Traceback (most recent call last):
  File "/home/benches/erpnext_user/env/lib/python3.8/site-packages/rq/worker.py", line 1020, in perform_job
    self.handle_job_success(job=job,
  File "/home/benches/erpnext_user/env/lib/python3.8/site-packages/rq/worker.py", line 970, in handle_job_success
    pipeline.watch(job.dependents_key)
  File "/home/benches/erpnext_user/env/lib/python3.8/site-packages/redis/client.py", line 4041, in watch
    return self.execute_command('WATCH', *names)
  File "/home/benches/erpnext_user/env/lib/python3.8/site-packages/redis/client.py", line 3822, in execute_command
    return self.immediate_execute_command(*args, **kwargs)
  File "/home/benches/erpnext_user/env/lib/python3.8/site-packages/redis/client.py", line 3836, in immediate_execute_command
    conn = self.connection_pool.get_connection(command_name,
  File "/home/benches/erpnext_user/env/lib/python3.8/site-packages/redis/connection.py", line 1202, in get_connection
    connection.connect()
  File "/home/benches/erpnext_user/env/lib/python3.8/site-packages/redis/connection.py", line 563, in connect
    raise ConnectionError(self._error_message(e))
redis.exceptions.ConnectionError: Error 111 connecting to localhost:11000. Connection refused.

2023-04-30 12:01:17,503 Worker rq:worker:f2ae139f808b41448a76bbd20409c056: found an unhandled exception, quitting...
Traceback (most recent call last):
  File "/home/benches/erpnext_user/env/lib/python3.8/site-packages/redis/connection.py", line 1198, in get_connection
    if connection.can_read():
  File "/home/benches/erpnext_user/env/lib/python3.8/site-packages/redis/connection.py", line 734, in can_read
    return self._parser.can_read(timeout)
  File "/home/benches/erpnext_user/env/lib/python3.8/site-packages/redis/connection.py", line 416, in can_read
    return self.read_from_socket(timeout=timeout,
  File "/home/benches/erpnext_user/env/lib/python3.8/site-packages/redis/connection.py", line 429, in read_from_socket
    raise ConnectionError(SERVER_CLOSED_CONNECTION_ERROR)
redis.exceptions.ConnectionError: Connection closed by server.

During handling of the above exception, another exception occurred:

Traceback (most recent call last):
  File "/home/benches/erpnext_user/env/lib/python3.8/site-packages/redis/connection.py", line 559, in connect
    sock = self._connect()
  File "/home/benches/erpnext_user/env/lib/python3.8/site-packages/redis/connection.py", line 615, in _connect
    raise err
  File "/home/benches/erpnext_user/env/lib/python3.8/site-packages/redis/connection.py", line 603, in _connect
    sock.connect(socket_address)
ConnectionRefusedError: [Errno 111] Connection refused

During handling of the above exception, another exception occurred:

Traceback (most recent call last):
  File "/home/benches/erpnext_user/env/lib/python3.8/site-packages/rq/worker.py", line 595, in work
    self.execute_job(job, queue)
  File "/home/benches/erpnext_user/env/lib/python3.8/site-packages/rq/worker.py", line 856, in execute_job
    self.monitor_work_horse(job, queue)
  File "/home/benches/erpnext_user/env/lib/python3.8/site-packages/rq/worker.py", line 818, in monitor_work_horse
    self.set_current_job_working_time(0)
  File "/home/benches/erpnext_user/env/lib/python3.8/site-packages/rq/worker.py", line 382, in set_current_job_working_time
    connection.hset(self.key, 'current_job_working_time', current_job_working_time)
  File "/home/benches/erpnext_user/env/lib/python3.8/site-packages/redis/client.py", line 3050, in hset
    return self.execute_command('HSET', name, *items)
  File "/home/benches/erpnext_user/env/lib/python3.8/site-packages/redis/client.py", line 898, in execute_command
    conn = self.connection or pool.get_connection(command_name, **options)
  File "/home/benches/erpnext_user/env/lib/python3.8/site-packages/redis/connection.py", line 1202, in get_connection
    connection.connect()
  File "/home/benches/erpnext_user/env/lib/python3.8/site-packages/redis/connection.py", line 563, in connect
    raise ConnectionError(self._error_message(e))
redis.exceptions.ConnectionError: Error 111 connecting to localhost:11000. Connection refused.
Traceback (most recent call last):
  File "/home/benches/erpnext_user/env/lib/python3.8/site-packages/redis/connection.py", line 559, in connect
    sock = self._connect()
  File "/home/benches/erpnext_user/env/lib/python3.8/site-packages/redis/connection.py", line 615, in _connect
    raise err
  File "/home/benches/erpnext_user/env/lib/python3.8/site-packages/redis/connection.py", line 603, in _connect
    sock.connect(socket_address)
ConnectionRefusedError: [Errno 111] Connection refused

During handling of the above exception, another exception occurred:

Traceback (most recent call last):
  File "/usr/lib/python3.8/runpy.py", line 194, in _run_module_as_main
    return _run_code(code, main_globals, None,
  File "/usr/lib/python3.8/runpy.py", line 87, in _run_code
    exec(code, run_globals)
  File "/home/benches/erpnext_user/apps/frappe/frappe/utils/bench_helper.py", line 110, in <module>
    main()
  File "/home/benches/erpnext_user/apps/frappe/frappe/utils/bench_helper.py", line 20, in main
    click.Group(commands=commands)(prog_name="bench")
  File "/home/benches/erpnext_user/env/lib/python3.8/site-packages/click/core.py", line 829, in __call__
    return self.main(*args, **kwargs)
  File "/home/benches/erpnext_user/env/lib/python3.8/site-packages/click/core.py", line 782, in main
    rv = self.invoke(ctx)
  File "/home/benches/erpnext_user/env/lib/python3.8/site-packages/click/core.py", line 1259, in invoke
    return _process_result(sub_ctx.command.invoke(sub_ctx))
  File "/home/benches/erpnext_user/env/lib/python3.8/site-packages/click/core.py", line 1259, in invoke
    return _process_result(sub_ctx.command.invoke(sub_ctx))
  File "/home/benches/erpnext_user/env/lib/python3.8/site-packages/click/core.py", line 1066, in invoke
    return ctx.invoke(self.callback, **ctx.params)
  File "/home/benches/erpnext_user/env/lib/python3.8/site-packages/click/core.py", line 610, in invoke
    return callback(*args, **kwargs)
  File "/home/benches/erpnext_user/apps/frappe/frappe/commands/scheduler.py", line 203, in start_worker
    start_worker(queue, quiet=quiet)
  File "/home/benches/erpnext_user/apps/frappe/frappe/utils/background_jobs.py", line 202, in start_worker
    Worker(queues, name=get_worker_name(queue)).work(
  File "/home/benches/erpnext_user/env/lib/python3.8/site-packages/rq/worker.py", line 626, in work
    self.register_death()
  File "/home/benches/erpnext_user/env/lib/python3.8/site-packages/rq/worker.py", line 326, in register_death
    p.execute()
  File "/home/benches/erpnext_user/env/lib/python3.8/site-packages/redis/client.py", line 4012, in execute
    conn = self.connection_pool.get_connection('MULTI',
  File "/home/benches/erpnext_user/env/lib/python3.8/site-packages/redis/connection.py", line 1192, in get_connection
    connection.connect()
  File "/home/benches/erpnext_user/env/lib/python3.8/site-packages/redis/connection.py", line 563, in connect
    raise ConnectionError(self._error_message(e))
redis.exceptions.ConnectionError: Error 111 connecting to localhost:11000. Connection refused.
Traceback (most recent call last):
  File "/home/benches/erpnext_user/env/lib/python3.8/site-packages/redis/connection.py", line 559, in connect
    sock = self._connect()
  File "/home/benches/erpnext_user/env/lib/python3.8/site-packages/redis/connection.py", line 615, in _connect
    raise err
  File "/home/benches/erpnext_user/env/lib/python3.8/site-packages/redis/connection.py", line 603, in _connect
    sock.connect(socket_address)
ConnectionRefusedError: [Errno 111] Connection refused

During handling of the above exception, another exception occurred:

Traceback (most recent call last):
  File "/usr/lib/python3.8/runpy.py", line 194, in _run_module_as_main
    return _run_code(code, main_globals, None,
  File "/usr/lib/python3.8/runpy.py", line 87, in _run_code
    exec(code, run_globals)
  File "/home/benches/erpnext_user/apps/frappe/frappe/utils/bench_helper.py", line 110, in <module>
    main()
  File "/home/benches/erpnext_user/apps/frappe/frappe/utils/bench_helper.py", line 20, in main
    click.Group(commands=commands)(prog_name="bench")
  File "/home/benches/erpnext_user/env/lib/python3.8/site-packages/click/core.py", line 829, in __call__
    return self.main(*args, **kwargs)
  File "/home/benches/erpnext_user/env/lib/python3.8/site-packages/click/core.py", line 782, in main
    rv = self.invoke(ctx)
  File "/home/benches/erpnext_user/env/lib/python3.8/site-packages/click/core.py", line 1259, in invoke
    return _process_result(sub_ctx.command.invoke(sub_ctx))
  File "/home/benches/erpnext_user/env/lib/python3.8/site-packages/click/core.py", line 1259, in invoke
    return _process_result(sub_ctx.command.invoke(sub_ctx))
  File "/home/benches/erpnext_user/env/lib/python3.8/site-packages/click/core.py", line 1066, in invoke
    return ctx.invoke(self.callback, **ctx.params)
  File "/home/benches/erpnext_user/env/lib/python3.8/site-packages/click/core.py", line 610, in invoke
    return callback(*args, **kwargs)
  File "/home/benches/erpnext_user/apps/frappe/frappe/commands/scheduler.py", line 203, in start_worker
    start_worker(queue, quiet=quiet)
  File "/home/benches/erpnext_user/apps/frappe/frappe/utils/background_jobs.py", line 202, in start_worker
    Worker(queues, name=get_worker_name(queue)).work(
  File "/home/benches/erpnext_user/env/lib/python3.8/site-packages/rq/worker.py", line 627, in work
    self.unsubscribe()
  File "/home/benches/erpnext_user/env/lib/python3.8/site-packages/rq/worker.py", line 532, in unsubscribe
    self.pubsub.unsubscribe()
  File "/home/benches/erpnext_user/env/lib/python3.8/site-packages/redis/client.py", line 3600, in unsubscribe
    return self.execute_command('UNSUBSCRIBE', *args)
  File "/home/benches/erpnext_user/env/lib/python3.8/site-packages/redis/client.py", line 3466, in execute_command
    self.connection = self.connection_pool.get_connection(
  File "/home/benches/erpnext_user/env/lib/python3.8/site-packages/redis/connection.py", line 1192, in get_connection
    connection.connect()
  File "/home/benches/erpnext_user/env/lib/python3.8/site-packages/redis/connection.py", line 563, in connect
    raise ConnectionError(self._error_message(e))
redis.exceptions.ConnectionError: Error 111 connecting to localhost:11000. Connection refused.
Exception in thread Thread-1:
Traceback (most recent call last):
  File "/usr/lib/python3.8/threading.py", line 932, in _bootstrap_inner
    self.run()
  File "/home/benches/erpnext_user/env/lib/python3.8/site-packages/redis/client.py", line 3718, in run
    pubsub.get_message(ignore_subscribe_messages=True,2023-04-30 13:28:31,947 Worker rq:worker:77eadb1aa99b46ddb159e0c12238115f: found an unhandled exception, quitting...
Traceback (most recent call last):
  File "/home/benches/erpnext_user/env/lib/python3.8/site-packages/rq/worker.py", line 595, in work
    self.execute_job(job, queue)
  File "/home/benches/erpnext_user/env/lib/python3.8/site-packages/rq/worker.py", line 856, in execute_job
    self.monitor_work_horse(job, queue)
  File "/home/benches/erpnext_user/env/lib/python3.8/site-packages/rq/worker.py", line 786, in monitor_work_horse
    retpid, ret_val = self.wait_for_horse()
  File "/home/benches/erpnext_user/env/lib/python3.8/site-packages/rq/worker.py", line 433, in wait_for_horse
    pid, stat = os.waitpid(self.horse_pid, 0)
  File "/home/benches/erpnext_user/env/lib/python3.8/site-packages/rq/worker.py", line 461, in request_stop
    self._shutdown()
  File "/home/benches/erpnext_user/env/lib/python3.8/site-packages/rq/worker.py", line 470, in _shutdown
    self.set_shutdown_requested_date()
  File "/home/benches/erpnext_user/env/lib/python3.8/site-packages/rq/worker.py", line 330, in set_shutdown_requested_date
    self.connection.hset(self.key, 'shutdown_requested_date', utcformat(utcnow()))
  File "/home/benches/erpnext_user/env/lib/python3.8/site-packages/redis/client.py", line 3050, in hset
    return self.execute_command('HSET', name, *items)
  File "/home/benches/erpnext_user/env/lib/python3.8/site-packages/redis/client.py", line 901, in execute_command
    return self.parse_response(conn, command_name, **options)
  File "/home/benches/erpnext_user/env/lib/python3.8/site-packages/redis/client.py", line 915, in parse_response
    response = connection.read_response()
  File "/home/benches/erpnext_user/env/lib/python3.8/site-packages/redis/connection.py", line 739, in read_response
    response = self._parser.read_response()
  File "/home/benches/erpnext_user/env/lib/python3.8/site-packages/redis/connection.py", line 470, in read_response
    self.read_from_socket()
  File "/home/benches/erpnext_user/env/lib/python3.8/site-packages/redis/connection.py", line 429, in read_from_socket
    raise ConnectionError(SERVER_CLOSED_CONNECTION_ERROR)
redis.exceptions.ConnectionError: Connection closed by server.

  File "/home/benches/erpnext_user/env/lib/python3.8/site-packages/redis/client.py", line 3617, in get_message
Traceback (most recent call last):
  File "/home/benches/erpnext_user/env/lib/python3.8/site-packages/redis/connection.py", line 559, in connect
    sock = self._connect()
  File "/home/benches/erpnext_user/env/lib/python3.8/site-packages/redis/connection.py", line 615, in _connect
    raise err
  File "/home/benches/erpnext_user/env/lib/python3.8/site-packages/redis/connection.py", line 603, in _connect
        response = self.parse_response(block=False, timeout=timeout)
sock.connect(socket_address)
  File "/home/benches/erpnext_user/env/lib/python3.8/site-packages/redis/client.py", line 3503, in parse_response
ConnectionRefusedError: [Errno 111] Connection refused
    if not block and not conn.can_read(timeout=timeout):
During handling of the above exception, another exception occurred:

Traceback (most recent call last):
  File "/usr/lib/python3.8/runpy.py", line 194, in _run_module_as_main

  File "/home/benches/erpnext_user/env/lib/python3.8/site-packages/redis/connection.py", line 734, in can_read
        return _run_code(code, main_globals, None,
  File "/usr/lib/python3.8/runpy.py", line 87, in _run_code
    return self._parser.can_read(timeout)exec(code, run_globals)

  File "/home/benches/erpnext_user/env/lib/python3.8/site-packages/redis/connection.py", line 416, in can_read
      File "/home/benches/erpnext_user/apps/frappe/frappe/utils/bench_helper.py", line 110, in <module>
return self.read_from_socket(timeout=timeout,    main()

  File "/home/benches/erpnext_user/env/lib/python3.8/site-packages/redis/connection.py", line 429, in read_from_socket
      File "/home/benches/erpnext_user/apps/frappe/frappe/utils/bench_helper.py", line 20, in main
    click.Group(commands=commands)(prog_name="bench")
  File "/home/benches/erpnext_user/env/lib/python3.8/site-packages/click/core.py", line 829, in __call__
    raise ConnectionError(SERVER_CLOSED_CONNECTION_ERROR)
redis.exceptions.ConnectionError: Connection closed by server.
return self.main(*args, **kwargs)
  File "/home/benches/erpnext_user/env/lib/python3.8/site-packages/click/core.py", line 782, in main
    rv = self.invoke(ctx)
  File "/home/benches/erpnext_user/env/lib/python3.8/site-packages/click/core.py", line 1259, in invoke
    return _process_result(sub_ctx.command.invoke(sub_ctx))
  File "/home/benches/erpnext_user/env/lib/python3.8/site-packages/click/core.py", line 1259, in invoke
    return _process_result(sub_ctx.command.invoke(sub_ctx))
  File "/home/benches/erpnext_user/env/lib/python3.8/site-packages/click/core.py", line 1066, in invoke
    return ctx.invoke(self.callback, **ctx.params)
  File "/home/benches/erpnext_user/env/lib/python3.8/site-packages/click/core.py", line 610, in invoke
    return callback(*args, **kwargs)
  File "/home/benches/erpnext_user/apps/frappe/frappe/commands/scheduler.py", line 203, in start_worker
    start_worker(queue, quiet=quiet)
  File "/home/benches/erpnext_user/apps/frappe/frappe/utils/background_jobs.py", line 202, in start_worker
    Worker(queues, name=get_worker_name(queue)).work(
  File "/home/benches/erpnext_user/env/lib/python3.8/site-packages/rq/worker.py", line 626, in work
    self.register_death()
  File "/home/benches/erpnext_user/env/lib/python3.8/site-packages/rq/worker.py", line 326, in register_death
    p.execute()
  File "/home/benches/erpnext_user/env/lib/python3.8/site-packages/redis/client.py", line 4012, in execute
    conn = self.connection_pool.get_connection('MULTI',
  File "/home/benches/erpnext_user/env/lib/python3.8/site-packages/redis/connection.py", line 1192, in get_connection
    connection.connect()
  File "/home/benches/erpnext_user/env/lib/python3.8/site-packages/redis/connection.py", line 563, in connect
    raise ConnectionError(self._error_message(e))
redis.exceptions.ConnectionError: Error 111 connecting to localhost:11000. Connection refused.
2023-04-30 13:28:35,401 Traceback (most recent call last):
  File "/home/benches/erpnext_user/env/lib/python3.8/site-packages/redis/connection.py", line 1198, in get_connection
    if connection.can_read():
  File "/home/benches/erpnext_user/env/lib/python3.8/site-packages/redis/connection.py", line 734, in can_read
    return self._parser.can_read(timeout)
  File "/home/benches/erpnext_user/env/lib/python3.8/site-packages/redis/connection.py", line 416, in can_read
    return self.read_from_socket(timeout=timeout,
  File "/home/benches/erpnext_user/env/lib/python3.8/site-packages/redis/connection.py", line 429, in read_from_socket
    raise ConnectionError(SERVER_CLOSED_CONNECTION_ERROR)
redis.exceptions.ConnectionError: Connection closed by server.

During handling of the above exception, another exception occurred:

Traceback (most recent call last):
  File "/home/benches/erpnext_user/env/lib/python3.8/site-packages/redis/connection.py", line 559, in connect
    sock = self._connect()
  File "/home/benches/erpnext_user/env/lib/python3.8/site-packages/redis/connection.py", line 615, in _connect
    raise err
  File "/home/benches/erpnext_user/env/lib/python3.8/site-packages/redis/connection.py", line 603, in _connect
    sock.connect(socket_address)
ConnectionRefusedError: [Errno 111] Connection refused

During handling of the above exception, another exception occurred:

Traceback (most recent call last):
  File "/home/benches/erpnext_user/env/lib/python3.8/site-packages/rq/worker.py", line 1020, in perform_job
    self.handle_job_success(job=job,
  File "/home/benches/erpnext_user/env/lib/python3.8/site-packages/rq/worker.py", line 970, in handle_job_success
    pipeline.watch(job.dependents_key)
  File "/home/benches/erpnext_user/env/lib/python3.8/site-packages/redis/client.py", line 4041, in watch
    return self.execute_command('WATCH', *names)
  File "/home/benches/erpnext_user/env/lib/python3.8/site-packages/redis/client.py", line 3822, in execute_command
    return self.immediate_execute_command(*args, **kwargs)
  File "/home/benches/erpnext_user/env/lib/python3.8/site-packages/redis/client.py", line 3836, in immediate_execute_command
    conn = self.connection_pool.get_connection(command_name,
  File "/home/benches/erpnext_user/env/lib/python3.8/site-packages/redis/connection.py", line 1202, in get_connection
    connection.connect()
  File "/home/benches/erpnext_user/env/lib/python3.8/site-packages/redis/connection.py", line 563, in connect
    raise ConnectionError(self._error_message(e))
redis.exceptions.ConnectionError: Error 111 connecting to localhost:11000. Connection refused.

/home/benches/erpnext_user/env/lib/python3.8/site-packages/botocore/httpsession.py:18: DeprecationWarning: 'urllib3.contrib.pyopenssl' module is deprecated and will be removed in a future release of urllib3 2.x. Read more in this issue: https://github.com/urllib3/urllib3/issues/2680
  from urllib3.contrib.pyopenssl import orig_util_SSLContext as SSLContext
/home/benches/erpnext_user/env/lib/python3.8/site-packages/botocore/httpsession.py:18: DeprecationWarning: 'urllib3.contrib.pyopenssl' module is deprecated and will be removed in a future release of urllib3 2.x. Read more in this issue: https://github.com/urllib3/urllib3/issues/2680
  from urllib3.contrib.pyopenssl import orig_util_SSLContext as SSLContext
fatal: No remote configured to list refs from.
/home/benches/erpnext_user/env/lib/python3.8/site-packages/botocore/httpsession.py:18: DeprecationWarning: 'urllib3.contrib.pyopenssl' module is deprecated and will be removed in a future release of urllib3 2.x. Read more in this issue: https://github.com/urllib3/urllib3/issues/2680
  from urllib3.contrib.pyopenssl import orig_util_SSLContext as SSLContext
fatal: No remote configured to list refs from.
/home/benches/erpnext_user/env/lib/python3.8/site-packages/botocore/httpsession.py:18: DeprecationWarning: 'urllib3.contrib.pyopenssl' module is deprecated and will be removed in a future release of urllib3 2.x. Read more in this issue: https://github.com/urllib3/urllib3/issues/2680
  from urllib3.contrib.pyopenssl import orig_util_SSLContext as SSLContext
/home/benches/erpnext_user/env/lib/python3.8/site-packages/botocore/httpsession.py:18: DeprecationWarning: 'urllib3.contrib.pyopenssl' module is deprecated and will be removed in a future release of urllib3 2.x. Read more in this issue: https://github.com/urllib3/urllib3/issues/2680
  from urllib3.contrib.pyopenssl import orig_util_SSLContext as SSLContext
Traceback (most recent call last):
  File "/home/benches/erpnext_user/env/lib/python3.8/site-packages/redis/connection.py", line 559, in connect
    sock = self._connect()
  File "/home/benches/erpnext_user/env/lib/python3.8/site-packages/redis/connection.py", line 615, in _connect
    raise err
  File "/home/benches/erpnext_user/env/lib/python3.8/site-packages/redis/connection.py", line 603, in _connect
    sock.connect(socket_address)
ConnectionRefusedError: [Errno 111] Connection refused

During handling of the above exception, another exception occurred:

Traceback (most recent call last):
  File "/usr/lib/python3.8/runpy.py", line 194, in _run_module_as_main
    return _run_code(code, main_globals, None,
  File "/usr/lib/python3.8/runpy.py", line 87, in _run_code
    exec(code, run_globals)
  File "/home/benches/erpnext_user/apps/frappe/frappe/utils/bench_helper.py", line 110, in <module>
    main()
  File "/home/benches/erpnext_user/apps/frappe/frappe/utils/bench_helper.py", line 20, in main
    click.Group(commands=commands)(prog_name="bench")
  File "/home/benches/erpnext_user/env/lib/python3.8/site-packages/click/core.py", line 829, in __call__
    return self.main(*args, **kwargs)
  File "/home/benches/erpnext_user/env/lib/python3.8/site-packages/click/core.py", line 782, in main
    rv = self.invoke(ctx)
  File "/home/benches/erpnext_user/env/lib/python3.8/site-packages/click/core.py", line 1259, in invoke
    return _process_result(sub_ctx.command.invoke(sub_ctx))
  File "/home/benches/erpnext_user/env/lib/python3.8/site-packages/click/core.py", line 1259, in invoke
    return _process_result(sub_ctx.command.invoke(sub_ctx))
  File "/home/benches/erpnext_user/env/lib/python3.8/site-packages/click/core.py", line 1066, in invoke
    return ctx.invoke(self.callback, **ctx.params)
  File "/home/benches/erpnext_user/env/lib/python3.8/site-packages/click/core.py", line 610, in invoke
    return callback(*args, **kwargs)
  File "/home/benches/erpnext_user/apps/frappe/frappe/commands/scheduler.py", line 203, in start_worker
    start_worker(queue, quiet=quiet)
  File "/home/benches/erpnext_user/apps/frappe/frappe/utils/background_jobs.py", line 202, in start_worker
    Worker(queues, name=get_worker_name(queue)).work(
  File "/home/benches/erpnext_user/env/lib/python3.8/site-packages/rq/worker.py", line 627, in work
    self.unsubscribe()
  File "/home/benches/erpnext_user/env/lib/python3.8/site-packages/rq/worker.py", line 532, in unsubscribe
    self.pubsub.unsubscribe()
  File "/home/benches/erpnext_user/env/lib/python3.8/site-packages/redis/client.py", line 3600, in unsubscribe
    return self.execute_command('UNSUBSCRIBE', *args)
  File "/home/benches/erpnext_user/env/lib/python3.8/site-packages/redis/client.py", line 3466, in execute_command
    self.connection = self.connection_pool.get_connection(
  File "/home/benches/erpnext_user/env/lib/python3.8/site-packages/redis/connection.py", line 1192, in get_connection
    connection.connect()
  File "/home/benches/erpnext_user/env/lib/python3.8/site-packages/redis/connection.py", line 563, in connect
    raise ConnectionError(self._error_message(e))
redis.exceptions.ConnectionError: Error 111 connecting to localhost:11000. Connection refused.
2023-05-04 18:04:10,559 Traceback (most recent call last):
  File "/home/benches/erpnext_user/env/lib/python3.8/site-packages/rq/worker.py", line 1013, in perform_job
    rv = job.perform()
  File "/home/benches/erpnext_user/env/lib/python3.8/site-packages/rq/job.py", line 709, in perform
    self._result = self._execute()
  File "/home/benches/erpnext_user/env/lib/python3.8/site-packages/rq/job.py", line 732, in _execute
    result = self.func(*self.args, **self.kwargs)
  File "/home/benches/erpnext_user/apps/frappe/frappe/utils/background_jobs.py", line 147, in execute_job
    retval = method(**kwargs)
  File "/home/benches/erpnext_user/apps/frappe/frappe/core/doctype/user/user.py", line 1124, in create_contact
    contact.insert(
  File "/home/benches/erpnext_user/apps/frappe/frappe/model/document.py", line 257, in insert
    self._validate_links()
  File "/home/benches/erpnext_user/apps/frappe/frappe/model/document.py", line 910, in _validate_links
    frappe.throw(_("Could not find {0}").format(msg), frappe.LinkValidationError)
  File "/home/benches/erpnext_user/apps/frappe/frappe/__init__.py", line 504, in throw
    msgprint(
  File "/home/benches/erpnext_user/apps/frappe/frappe/__init__.py", line 479, in msgprint
    _raise_exception()
  File "/home/benches/erpnext_user/apps/frappe/frappe/__init__.py", line 434, in _raise_exception
    raise raise_exception(msg)
frappe.exceptions.LinkValidationError: Could not find User Id: nyashamusanhu@gmail.com

2023-05-04 18:10:51,938 Traceback (most recent call last):
  File "/home/benches/erpnext_user/env/lib/python3.8/site-packages/rq/worker.py", line 1013, in perform_job
    rv = job.perform()
  File "/home/benches/erpnext_user/env/lib/python3.8/site-packages/rq/job.py", line 709, in perform
    self._result = self._execute()
  File "/home/benches/erpnext_user/env/lib/python3.8/site-packages/rq/job.py", line 732, in _execute
    result = self.func(*self.args, **self.kwargs)
  File "/home/benches/erpnext_user/apps/frappe/frappe/utils/background_jobs.py", line 147, in execute_job
    retval = method(**kwargs)
  File "/home/benches/erpnext_user/apps/frappe/frappe/core/doctype/user/user.py", line 1124, in create_contact
    contact.insert(
  File "/home/benches/erpnext_user/apps/frappe/frappe/model/document.py", line 257, in insert
    self._validate_links()
  File "/home/benches/erpnext_user/apps/frappe/frappe/model/document.py", line 910, in _validate_links
    frappe.throw(_("Could not find {0}").format(msg), frappe.LinkValidationError)
  File "/home/benches/erpnext_user/apps/frappe/frappe/__init__.py", line 504, in throw
    msgprint(
  File "/home/benches/erpnext_user/apps/frappe/frappe/__init__.py", line 479, in msgprint
    _raise_exception()
  File "/home/benches/erpnext_user/apps/frappe/frappe/__init__.py", line 434, in _raise_exception
    raise raise_exception(msg)
frappe.exceptions.LinkValidationError: Could not find User Id: nyasham@lcvssc.co.za

2023-05-04 18:14:48,792 Traceback (most recent call last):
  File "/home/benches/erpnext_user/env/lib/python3.8/site-packages/rq/worker.py", line 1013, in perform_job
    rv = job.perform()
  File "/home/benches/erpnext_user/env/lib/python3.8/site-packages/rq/job.py", line 709, in perform
    self._result = self._execute()
  File "/home/benches/erpnext_user/env/lib/python3.8/site-packages/rq/job.py", line 732, in _execute
    result = self.func(*self.args, **self.kwargs)
  File "/home/benches/erpnext_user/apps/frappe/frappe/utils/background_jobs.py", line 147, in execute_job
    retval = method(**kwargs)
  File "/home/benches/erpnext_user/apps/frappe/frappe/core/doctype/user/user.py", line 1124, in create_contact
    contact.insert(
  File "/home/benches/erpnext_user/apps/frappe/frappe/model/document.py", line 257, in insert
    self._validate_links()
  File "/home/benches/erpnext_user/apps/frappe/frappe/model/document.py", line 910, in _validate_links
    frappe.throw(_("Could not find {0}").format(msg), frappe.LinkValidationError)
  File "/home/benches/erpnext_user/apps/frappe/frappe/__init__.py", line 504, in throw
    msgprint(
  File "/home/benches/erpnext_user/apps/frappe/frappe/__init__.py", line 479, in msgprint
    _raise_exception()
  File "/home/benches/erpnext_user/apps/frappe/frappe/__init__.py", line 434, in _raise_exception
    raise raise_exception(msg)
frappe.exceptions.LinkValidationError: Could not find User Id: gymtrainer@lcvssc.co.za

Exception in thread Thread-1:
Traceback (most recent call last):
  File "/usr/lib/python3.8/threading.py", line 932, in _bootstrap_inner
    self.run()
  File "/home/benches/erpnext_user/env/lib/python3.8/site-packages/redis/client.py", line 3718, in run
    pubsub.get_message(ignore_subscribe_messages=True,
  File "/home/benches/erpnext_user/env/lib/python3.8/site-packages/redis/client.py", line 3617, in get_message
    response = self.parse_response(block=False, timeout=timeout)
  File "/home/benches/erpnext_user/env/lib/python3.8/site-packages/redis/client.py", line 3503, in parse_response
    if not block and not conn.can_read(timeout=timeout):
  File "/home/benches/erpnext_user/env/lib/python3.8/site-packages/redis/connection.py", line 734, in can_read
    return self._parser.can_read(timeout)
  File "/home/benches/erpnext_user/env/lib/python3.8/site-packages/redis/connection.py", line 416, in can_read
    return self.read_from_socket(timeout=timeout,
  File "/home/benches/erpnext_user/env/lib/python3.8/site-packages/redis/connection.py", line 429, in read_from_socket
    raise ConnectionError(SERVER_CLOSED_CONNECTION_ERROR)
redis.exceptions.ConnectionError: Connection closed by server.
